2023-06-07 15:51:03,922 Scheduler started 
2023-06-07 16:17:21,044 No error handlers are registered, logging exception. 
Traceback (most recent call last):
  File "/root/MyBot/venv/lib/python3.11/site-packages/telegram/ext/dispatcher.py", line 557, in process_update
    handler.handle_update(update, self, check, context)
  File "/root/MyBot/venv/lib/python3.11/site-packages/telegram/ext/handler.py", line 199, in handle_update
    return self.callback(update, context)
           ^^^^^^^^^^^^^^^^^^^^^^^^^^^^^^
  File "/root/MyBot/bot.py", line 22, in start
    update.callback_query.edit_message_text(
  File "/root/MyBot/venv/lib/python3.11/site-packages/telegram/callbackquery.py", line 216, in edit_message_text
    return self.message.edit_text(
           ^^^^^^^^^^^^^^^^^^^^^^^
  File "/root/MyBot/venv/lib/python3.11/site-packages/telegram/message.py", line 2246, in edit_text
    return self.bot.edit_message_text(
           ^^^^^^^^^^^^^^^^^^^^^^^^^^^
  File "/root/MyBot/venv/lib/python3.11/site-packages/telegram/bot.py", line 134, in decorator
    result = func(*args, **kwargs)
             ^^^^^^^^^^^^^^^^^^^^^
  File "/root/MyBot/venv/lib/python3.11/site-packages/telegram/bot.py", line 2861, in edit_message_text
    return self._message(
           ^^^^^^^^^^^^^^
  File "/root/MyBot/venv/lib/python3.11/site-packages/telegram/ext/extbot.py", line 203, in _message
    result = super()._message(
             ^^^^^^^^^^^^^^^^^
  File "/root/MyBot/venv/lib/python3.11/site-packages/telegram/bot.py", line 344, in _message
    result = self._post(endpoint, data, timeout=timeout, api_kwargs=api_kwargs)
             ^^^^^^^^^^^^^^^^^^^^^^^^^^^^^^^^^^^^^^^^^^^^^^^^^^^^^^^^^^^^^^^^^^
  File "/root/MyBot/venv/lib/python3.11/site-packages/telegram/bot.py", line 299, in _post
    return self.request.post(
           ^^^^^^^^^^^^^^^^^^
  File "/root/MyBot/venv/lib/python3.11/site-packages/telegram/utils/request.py", line 361, in post
    result = self._request_wrapper(
             ^^^^^^^^^^^^^^^^^^^^^^
  File "/root/MyBot/venv/lib/python3.11/site-packages/telegram/utils/request.py", line 279, in _request_wrapper
    raise BadRequest(message)
telegram.error.BadRequest: Message is not modified: specified new message content and reply markup are exactly the same as a current content and reply markup of the message
2023-06-07 16:30:44,254 Added job "256144138" to job store "default" 
2023-06-07 16:31:00,002 Running job "256144138 (trigger: cron[day_of_week='0,1,2,3,4,5,6', hour='16', minute='31', second='0'], next run at: 2023-06-07 16:31:00 MSK)" (scheduled at 2023-06-07 16:31:00+03:00) 
2023-06-07 16:31:00,277 Job "256144138 (trigger: cron[day_of_week='0,1,2,3,4,5,6', hour='16', minute='31', second='0'], next run at: 2023-06-08 16:31:00 MSK)" executed successfully 
2023-06-07 16:40:48,512 Added job "728916533" to job store "default" 
2023-06-07 17:51:04,366 Removed job bf9e5f34f1054e8d9940d7333397d91c 
2023-06-07 17:51:04,369 Added job "728916533" to job store "default" 
2023-06-07 17:52:00,002 Running job "728916533 (trigger: cron[day_of_week='0,1,2,3,4,5,6', hour='17', minute='52', second='0'], next run at: 2023-06-08 17:52:00 MSK)" (scheduled at 2023-06-07 17:52:00+03:00) 
2023-06-07 17:52:00,196 Job "728916533 (trigger: cron[day_of_week='0,1,2,3,4,5,6', hour='17', minute='52', second='0'], next run at: 2023-06-08 17:52:00 MSK)" executed successfully 
2023-06-07 18:12:13,058 Received signal 15 (SIGTERM), stopping... 
2023-06-07 18:12:13,067 Scheduler has been shut down 
2023-06-08 04:56:26,587 Scheduler started 
2023-06-08 04:58:52,638 No error handlers are registered, logging exception. 
Traceback (most recent call last):
  File "/root/MyBot/venv/lib/python3.11/site-packages/telegram/ext/dispatcher.py", line 557, in process_update
    handler.handle_update(update, self, check, context)
  File "/root/MyBot/venv/lib/python3.11/site-packages/telegram/ext/handler.py", line 199, in handle_update
    return self.callback(update, context)
           ^^^^^^^^^^^^^^^^^^^^^^^^^^^^^^
  File "/root/MyBot/bot.py", line 99, in chvakson_response
    context.bot.send_photo(chat_id=update.message.from_user.id)
  File "/root/MyBot/venv/lib/python3.11/site-packages/telegram/bot.py", line 134, in decorator
    result = func(*args, **kwargs)
             ^^^^^^^^^^^^^^^^^^^^^
TypeError: Bot.send_photo() missing 1 required positional argument: 'photo'
2023-06-08 06:17:24,179 No error handlers are registered, logging exception. 
Traceback (most recent call last):
  File "/root/MyBot/venv/lib/python3.11/site-packages/telegram/ext/dispatcher.py", line 557, in process_update
    handler.handle_update(update, self, check, context)
  File "/root/MyBot/venv/lib/python3.11/site-packages/telegram/ext/handler.py", line 199, in handle_update
    return self.callback(update, context)
           ^^^^^^^^^^^^^^^^^^^^^^^^^^^^^^
  File "/root/MyBot/bot.py", line 96, in chvakson_response
    if update.message.from_user.username == 'Dr_chvakson':
       ^^^^^^^^^^^^^^^^^^^^^^^^
AttributeError: 'NoneType' object has no attribute 'from_user'
2023-06-08 09:38:41,966 Added job "728916533" to job store "default" 
2023-06-08 09:39:31,331 Received signal 15 (SIGTERM), stopping... 
2023-06-08 09:39:31,333 Scheduler has been shut down 
2023-06-08 09:59:39,369 Adding job tentatively -- it will be properly scheduled when the scheduler starts 
2023-06-08 09:59:39,370 Adding job tentatively -- it will be properly scheduled when the scheduler starts 
2023-06-08 09:59:39,579 Added job "256144138" to job store "default" 
2023-06-08 09:59:39,579 Added job "728916533" to job store "default" 
2023-06-08 09:59:39,579 Scheduler started 
2023-06-08 13:17:47,853 Received signal 15 (SIGTERM), stopping... 
2023-06-08 13:17:47,855 Scheduler has been shut down 
2023-06-08 14:46:00,442 Adding job tentatively -- it will be properly scheduled when the scheduler starts 
2023-06-08 14:46:00,443 Adding job tentatively -- it will be properly scheduled when the scheduler starts 
2023-06-08 14:46:01,818 Added job "256144138" to job store "default" 
2023-06-08 14:46:01,818 Added job "728916533" to job store "default" 
2023-06-08 14:46:01,818 Scheduler started 
2023-06-08 15:01:21,721 Retrying (Retry(total=2, connect=None, read=None, redirect=None)) after connection broken by 'NewConnectionError('<telegram.vendor.ptb_urllib3.urllib3.connection.VerifiedHTTPSConnection object at 0x7f0ecc638150>: Failed to establish a new connection: [Errno -3] Temporary failure in name resolution')': /bot1682993335:AAEZT6kWtm1oMhui0FXnhaIF1SdqPGBfnf8/getUpdates 
2023-06-08 15:01:41,761 Retrying (Retry(total=1, connect=None, read=None, redirect=None)) after connection broken by 'NewConnectionError('<telegram.vendor.ptb_urllib3.urllib3.connection.VerifiedHTTPSConnection object at 0x7f0ecc639410>: Failed to establish a new connection: [Errno -3] Temporary failure in name resolution')': /bot1682993335:AAEZT6kWtm1oMhui0FXnhaIF1SdqPGBfnf8/getUpdates 
2023-06-08 15:38:01,105 Removed job ab3b7e11bf924d7eb5983a264bea6310 
2023-06-08 15:38:01,107 Added job "728916533" to job store "default" 
2023-06-08 15:39:17,312 Removed job 1947d469155f420e88783b90a02dce07 
2023-06-08 15:39:17,314 Added job "728916533" to job store "default" 
2023-06-08 15:40:00,001 Running job "728916533 (trigger: cron[day_of_week='0,1,2,3,4,5,6', hour='15', minute='40', second='0'], next run at: 2023-06-08 15:40:00 MSK)" (scheduled at 2023-06-08 15:40:00+03:00) 
2023-06-08 15:40:00,351 Job "728916533 (trigger: cron[day_of_week='0,1,2,3,4,5,6', hour='15', minute='40', second='0'], next run at: 2023-06-09 15:40:00 MSK)" executed successfully 
2023-06-08 16:31:00,013 Running job "256144138 (trigger: cron[day_of_week='0,1,2,3,4,5,6', hour='16', minute='31', second='0'], next run at: 2023-06-09 16:31:00 MSK)" (scheduled at 2023-06-08 16:31:00+03:00) 
2023-06-08 16:31:00,408 Job "256144138 (trigger: cron[day_of_week='0,1,2,3,4,5,6', hour='16', minute='31', second='0'], next run at: 2023-06-09 16:31:00 MSK)" executed successfully 
2023-06-09 04:48:12,680 Retrying (Retry(total=2, connect=None, read=None, redirect=None)) after connection broken by 'NewConnectionError('<telegram.vendor.ptb_urllib3.urllib3.connection.VerifiedHTTPSConnection object at 0x7f0ecc6398d0>: Failed to establish a new connection: [Errno -3] Temporary failure in name resolution')': /bot1682993335:AAEZT6kWtm1oMhui0FXnhaIF1SdqPGBfnf8/getUpdates 
2023-06-09 05:00:09,436 Received signal 15 (SIGTERM), stopping... 
2023-06-09 05:00:09,441 Scheduler has been shut down 
2023-06-09 05:00:25,391 Adding job tentatively -- it will be properly scheduled when the scheduler starts 
2023-06-09 05:00:25,391 Adding job tentatively -- it will be properly scheduled when the scheduler starts 
2023-06-09 05:00:25,597 Added job "256144138" to job store "default" 
2023-06-09 05:00:25,598 Added job "728916533" to job store "default" 
2023-06-09 05:00:25,598 Scheduler started 
2023-06-09 12:05:57,846 Retrying (Retry(total=2, connect=None, read=None, redirect=None)) after connection broken by 'NewConnectionError('<telegram.vendor.ptb_urllib3.urllib3.connection.VerifiedHTTPSConnection object at 0x7f52a8a35ad0>: Failed to establish a new connection: [Errno -3] Temporary failure in name resolution')': /bot1682993335:AAEZT6kWtm1oMhui0FXnhaIF1SdqPGBfnf8/getUpdates 
2023-06-09 15:40:00,003 Running job "728916533 (trigger: cron[day_of_week='0,1,2,3,4,5,6', hour='15', minute='40', second='0'], next run at: 2023-06-09 15:40:00 MSK)" (scheduled at 2023-06-09 15:40:00+03:00) 
2023-06-09 15:40:00,394 Job "728916533 (trigger: cron[day_of_week='0,1,2,3,4,5,6', hour='15', minute='40', second='0'], next run at: 2023-06-10 15:40:00 MSK)" executed successfully 
2023-06-09 16:31:00,011 Running job "256144138 (trigger: cron[day_of_week='0,1,2,3,4,5,6', hour='16', minute='31', second='0'], next run at: 2023-06-10 16:31:00 MSK)" (scheduled at 2023-06-09 16:31:00+03:00) 
2023-06-09 16:31:00,403 Job "256144138 (trigger: cron[day_of_week='0,1,2,3,4,5,6', hour='16', minute='31', second='0'], next run at: 2023-06-10 16:31:00 MSK)" executed successfully 
2023-06-09 18:04:30,294 No error handlers are registered, logging exception. 
Traceback (most recent call last):
  File "/root/MyBot/venv/lib/python3.11/site-packages/telegram/ext/dispatcher.py", line 557, in process_update
    handler.handle_update(update, self, check, context)
  File "/root/MyBot/venv/lib/python3.11/site-packages/telegram/ext/handler.py", line 199, in handle_update
    return self.callback(update, context)
           ^^^^^^^^^^^^^^^^^^^^^^^^^^^^^^
  File "/root/MyBot/bot.py", line 78, in get_info
    update.callback_query.edit_message_text(
  File "/root/MyBot/venv/lib/python3.11/site-packages/telegram/callbackquery.py", line 216, in edit_message_text
    return self.message.edit_text(
           ^^^^^^^^^^^^^^^^^^^^^^^
  File "/root/MyBot/venv/lib/python3.11/site-packages/telegram/message.py", line 2246, in edit_text
    return self.bot.edit_message_text(
           ^^^^^^^^^^^^^^^^^^^^^^^^^^^
  File "/root/MyBot/venv/lib/python3.11/site-packages/telegram/bot.py", line 134, in decorator
    result = func(*args, **kwargs)
             ^^^^^^^^^^^^^^^^^^^^^
  File "/root/MyBot/venv/lib/python3.11/site-packages/telegram/bot.py", line 2861, in edit_message_text
    return self._message(
           ^^^^^^^^^^^^^^
  File "/root/MyBot/venv/lib/python3.11/site-packages/telegram/ext/extbot.py", line 203, in _message
    result = super()._message(
             ^^^^^^^^^^^^^^^^^
  File "/root/MyBot/venv/lib/python3.11/site-packages/telegram/bot.py", line 344, in _message
    result = self._post(endpoint, data, timeout=timeout, api_kwargs=api_kwargs)
             ^^^^^^^^^^^^^^^^^^^^^^^^^^^^^^^^^^^^^^^^^^^^^^^^^^^^^^^^^^^^^^^^^^
  File "/root/MyBot/venv/lib/python3.11/site-packages/telegram/bot.py", line 299, in _post
    return self.request.post(
           ^^^^^^^^^^^^^^^^^^
  File "/root/MyBot/venv/lib/python3.11/site-packages/telegram/utils/request.py", line 361, in post
    result = self._request_wrapper(
             ^^^^^^^^^^^^^^^^^^^^^^
  File "/root/MyBot/venv/lib/python3.11/site-packages/telegram/utils/request.py", line 279, in _request_wrapper
    raise BadRequest(message)
telegram.error.BadRequest: Message is not modified: specified new message content and reply markup are exactly the same as a current content and reply markup of the message
2023-06-10 02:43:22,586 Error while getting Updates: urllib3 HTTPError ('Connection aborted.', RemoteDisconnected('Remote end closed connection without response')) 
2023-06-10 02:43:22,588 No error handlers are registered, logging exception. 
Traceback (most recent call last):
  File "/root/MyBot/venv/lib/python3.11/site-packages/telegram/vendor/ptb_urllib3/urllib3/connectionpool.py", line 614, in urlopen
    httplib_response = self._make_request(conn, method, url,
                       ^^^^^^^^^^^^^^^^^^^^^^^^^^^^^^^^^^^^^
  File "/root/MyBot/venv/lib/python3.11/site-packages/telegram/vendor/ptb_urllib3/urllib3/connectionpool.py", line 402, in _make_request
    six.raise_from(e, None)
  File "<string>", line 2, in raise_from
  File "/root/MyBot/venv/lib/python3.11/site-packages/telegram/vendor/ptb_urllib3/urllib3/connectionpool.py", line 398, in _make_request
    httplib_response = conn.getresponse()
                       ^^^^^^^^^^^^^^^^^^
  File "/usr/lib/python3.11/http/client.py", line 1375, in getresponse
    response.begin()
  File "/usr/lib/python3.11/http/client.py", line 318, in begin
    version, status, reason = self._read_status()
                              ^^^^^^^^^^^^^^^^^^^
  File "/usr/lib/python3.11/http/client.py", line 287, in _read_status
    raise RemoteDisconnected("Remote end closed connection without"
http.client.RemoteDisconnected: Remote end closed connection without response

During handling of the above exception, another exception occurred:

Traceback (most recent call last):
  File "/root/MyBot/venv/lib/python3.11/site-packages/telegram/utils/request.py", line 259, in _request_wrapper
    resp = self._con_pool.request(*args, **kwargs)
           ^^^^^^^^^^^^^^^^^^^^^^^^^^^^^^^^^^^^^^^
  File "/root/MyBot/venv/lib/python3.11/site-packages/telegram/vendor/ptb_urllib3/urllib3/request.py", line 68, in request
    return self.request_encode_body(method, url, fields=fields,
           ^^^^^^^^^^^^^^^^^^^^^^^^^^^^^^^^^^^^^^^^^^^^^^^^^^^^
  File "/root/MyBot/venv/lib/python3.11/site-packages/telegram/vendor/ptb_urllib3/urllib3/request.py", line 148, in request_encode_body
    return self.urlopen(method, url, **extra_kw)
           ^^^^^^^^^^^^^^^^^^^^^^^^^^^^^^^^^^^^^
  File "/root/MyBot/venv/lib/python3.11/site-packages/telegram/vendor/ptb_urllib3/urllib3/poolmanager.py", line 244, in urlopen
    response = conn.urlopen(method, u.request_uri, **kw)
               ^^^^^^^^^^^^^^^^^^^^^^^^^^^^^^^^^^^^^^^^^
  File "/root/MyBot/venv/lib/python3.11/site-packages/telegram/vendor/ptb_urllib3/urllib3/connectionpool.py", line 665, in urlopen
    retries = retries.increment(method, url, error=e, _pool=self,
              ^^^^^^^^^^^^^^^^^^^^^^^^^^^^^^^^^^^^^^^^^^^^^^^^^^^
  File "/root/MyBot/venv/lib/python3.11/site-packages/telegram/vendor/ptb_urllib3/urllib3/util/retry.py", line 347, in increment
    raise six.reraise(type(error), error, _stacktrace)
          ^^^^^^^^^^^^^^^^^^^^^^^^^^^^^^^^^^^^^^^^^^^^
  File "/root/MyBot/venv/lib/python3.11/site-packages/telegram/vendor/ptb_urllib3/urllib3/packages/six.py", line 685, in reraise
    raise value.with_traceback(tb)
  File "/root/MyBot/venv/lib/python3.11/site-packages/telegram/vendor/ptb_urllib3/urllib3/connectionpool.py", line 614, in urlopen
    httplib_response = self._make_request(conn, method, url,
                       ^^^^^^^^^^^^^^^^^^^^^^^^^^^^^^^^^^^^^
  File "/root/MyBot/venv/lib/python3.11/site-packages/telegram/vendor/ptb_urllib3/urllib3/connectionpool.py", line 402, in _make_request
    six.raise_from(e, None)
  File "<string>", line 2, in raise_from
  File "/root/MyBot/venv/lib/python3.11/site-packages/telegram/vendor/ptb_urllib3/urllib3/connectionpool.py", line 398, in _make_request
    httplib_response = conn.getresponse()
                       ^^^^^^^^^^^^^^^^^^
  File "/usr/lib/python3.11/http/client.py", line 1375, in getresponse
    response.begin()
  File "/usr/lib/python3.11/http/client.py", line 318, in begin
    version, status, reason = self._read_status()
                              ^^^^^^^^^^^^^^^^^^^
  File "/usr/lib/python3.11/http/client.py", line 287, in _read_status
    raise RemoteDisconnected("Remote end closed connection without"
telegram.vendor.ptb_urllib3.urllib3.exceptions.ProtocolError: ('Connection aborted.', RemoteDisconnected('Remote end closed connection without response'))

The above exception was the direct cause of the following exception:

Traceback (most recent call last):
  File "/root/MyBot/venv/lib/python3.11/site-packages/telegram/ext/updater.py", line 651, in _network_loop_retry
    if not action_cb():
           ^^^^^^^^^^^
  File "/root/MyBot/venv/lib/python3.11/site-packages/telegram/ext/updater.py", line 602, in polling_action_cb
    updates = self.bot.get_updates(
              ^^^^^^^^^^^^^^^^^^^^^
  File "/root/MyBot/venv/lib/python3.11/site-packages/telegram/ext/extbot.py", line 228, in get_updates
    updates = super().get_updates(
              ^^^^^^^^^^^^^^^^^^^^
  File "/root/MyBot/venv/lib/python3.11/site-packages/telegram/bot.py", line 134, in decorator
    result = func(*args, **kwargs)
             ^^^^^^^^^^^^^^^^^^^^^
  File "/root/MyBot/venv/lib/python3.11/site-packages/telegram/bot.py", line 3140, in get_updates
    self._post(
  File "/root/MyBot/venv/lib/python3.11/site-packages/telegram/bot.py", line 299, in _post
    return self.request.post(
           ^^^^^^^^^^^^^^^^^^
  File "/root/MyBot/venv/lib/python3.11/site-packages/telegram/utils/request.py", line 361, in post
    result = self._request_wrapper(
             ^^^^^^^^^^^^^^^^^^^^^^
  File "/root/MyBot/venv/lib/python3.11/site-packages/telegram/utils/request.py", line 265, in _request_wrapper
    raise NetworkError(f'urllib3 HTTPError {error}') from error
telegram.error.NetworkError: urllib3 HTTPError ('Connection aborted.', RemoteDisconnected('Remote end closed connection without response'))
2023-06-10 03:32:41,222 Retrying (Retry(total=2, connect=None, read=None, redirect=None)) after connection broken by 'NewConnectionError('<telegram.vendor.ptb_urllib3.urllib3.connection.VerifiedHTTPSConnection object at 0x7f52a45a2450>: Failed to establish a new connection: [Errno -3] Temporary failure in name resolution')': /bot1682993335:AAEZT6kWtm1oMhui0FXnhaIF1SdqPGBfnf8/getUpdates 
2023-06-10 10:54:43,653 Received signal 15 (SIGTERM), stopping... 
2023-06-10 10:54:43,663 Scheduler has been shut down 
2023-06-10 10:55:22,945 Adding job tentatively -- it will be properly scheduled when the scheduler starts 
2023-06-10 10:55:22,946 Adding job tentatively -- it will be properly scheduled when the scheduler starts 
2023-06-10 10:55:23,162 Added job "256144138" to job store "default" 
2023-06-10 10:55:23,163 Added job "728916533" to job store "default" 
2023-06-10 10:55:23,163 Scheduler started 
2023-06-10 11:04:37,837 Received signal 15 (SIGTERM), stopping... 
2023-06-10 11:04:37,839 Scheduler has been shut down 
2023-06-10 17:09:19,390 Adding job tentatively -- it will be properly scheduled when the scheduler starts 
2023-06-10 17:09:19,391 Adding job tentatively -- it will be properly scheduled when the scheduler starts 
2023-06-10 17:09:19,641 Added job "256144138" to job store "default" 
2023-06-10 17:09:19,642 Added job "728916533" to job store "default" 
2023-06-10 17:09:19,642 Scheduler started 
